//일부로 오류를 내 try catch의 작동을 확인하는 코드

try 
{
    printMessage('hello'); 
} catch (e) {
    console.log('error:', e);
}

console.log('program finished');

